<?xml version="1.0"?>
<robot name="two_wheel_robot">

  <!-- Base Link -->
  <link name="base_link">
    <visual>
      <geometry>
        <box size="0.3 0.15 0.2"/>
      </geometry>
      <origin xyz="0 0 0.05" rpy="0 0 0"/>
      <material name="blue">
        <color rgba="0.0 0.0 1.0 1.0"/>
      </material>
    </visual>
    
    <collision>
      <geometry>
        <box size="0.3 0.15 0.2"/>
      </geometry>
      <origin xyz="0 0 0.05" rpy="0 0 0"/>
    </collision>

    <inertial>
      <mass value="3.0"/>
      <origin xyz="0 0 0.05" rpy="0 0 0"/>
      <inertia ixx="0.0375" ixy="0.0" ixz="0.0" iyy="0.0675" iyz="0.0" izz="0.09"/>
    </inertial>
  </link>

  <!-- Left Wheel -->
  <link name="left_wheel">
    <visual>
      <geometry>
        <cylinder radius="0.05" length="0.04"/>
      </geometry>
      <material name="black">
        <color rgba="0.0 0.0 0.0 1.0"/>
      </material>
    </visual>
    
    <collision>
      <geometry>
        <cylinder radius="0.05" length="0.04"/>
      </geometry>
    </collision>
    
    <inertial>
      <mass value="0.3"/>
      <inertia ixx="0.0005" ixy="0.0" ixz="0.0" iyy="0.0005" iyz="0.0" izz="0.00075"/>
    </inertial>
  </link>

  <!-- Right Wheel -->
  <link name="right_wheel">
    <visual>
      <geometry>
        <cylinder radius="0.05" length="0.04"/>
      </geometry>
      <material name="black">
        <color rgba="0.0 0.0 0.0 1.0"/>
      </material>
    </visual>
    
    <collision>
      <geometry>
        <cylinder radius="0.05" length="0.04"/>
      </geometry>
    </collision>
    
    <inertial>
      <mass value="0.3"/>
      <inertia ixx="0.0005" ixy="0.0" ixz="0.0" iyy="0.0005" iyz="0.0" izz="0.00075"/>
    </inertial>
  </link>

  <!-- Caster Wheel -->
  <link name="caster_wheel">
    <visual>
      <geometry>
        <sphere radius="0.05"/>
      </geometry>
      <material name="grey">
        <color rgba="0.5 0.5 0.5 1.0"/>
      </material>
    </visual>
    
    <collision>
      <geometry>
        <sphere radius="0.05"/>
      </geometry>
    </collision>
    
    <inertial>
      <mass value="0.1"/>
      <inertia ixx="0.0001" ixy="0.0" ixz="0.0" iyy="0.0001" iyz="0.0" izz="0.0001"/>
    </inertial>
  </link>

  <!-- Lidar Link -->
  <link name="lidar_link">
    <visual>
      <geometry>
        <cylinder radius="0.05" length="0.07"/>
      </geometry>
      <material name="red">
        <color rgba="1.0 0.0 0.0 1.0"/>
      </material>
    </visual>
    
    <collision>
      <geometry>
        <cylinder radius="0.05" length="0.07"/>
      </geometry>
    </collision>
    
    <inertial>
      <mass value="0.2"/>
      <inertia ixx="0.001" ixy="0.0" ixz="0.0" iyy="0.001" iyz="0.0" izz="0.001"/>
    </inertial>
  </link>

  <!-- Camera Link -->
  <link name="camera_link">
    <visual>
      <geometry>
        <box size="0.025 0.09 0.025"/>
      </geometry>
      <origin xyz="0 0 0" rpy="0 0 0"/>
      <material name="camera_grey">
        <color rgba="0.5 0.5 0.5 1.0"/>
      </material>
    </visual>
    
    <collision>
      <geometry>
        <box size="0.025 0.09 0.025"/>
      </geometry>
      <origin xyz="0 0 0" rpy="0 0 0"/>
    </collision>
    
    <inertial>
      <mass value="0.072"/>
      <origin xyz="0 0 0" rpy="0 0 0"/>
      <inertia ixx="0.00001" ixy="0.0" ixz="0.0" iyy="0.00001" iyz="0.0" izz="0.00001"/>
    </inertial>
  </link>

  <!-- Camera Optical Frame (for ROS convention: x=right, y=down, z=forward) -->
  <link name="camera_optical_link"/>

  <!-- Left Wheel Joint -->
  <joint name="left_wheel_joint" type="continuous">
    <parent link="base_link"/>
    <child link="left_wheel"/>
    <origin xyz="-0.075 -0.0875 -0.05" rpy="1.5708 0.0 0.0"/>
    <axis xyz="0 0 -1"/>
  </joint>

  <!-- Right Wheel Joint -->
  <joint name="right_wheel_joint" type="continuous">
    <parent link="base_link"/>
    <child link="right_wheel"/>
    <origin xyz="-0.075 0.0875 -0.05" rpy="1.5708 0.0 0.0"/>
    <axis xyz="0 0 -1"/>
  </joint>

  <!-- Caster Wheel Joint (fixed to base) -->
  <joint name="caster_wheel_joint" type="fixed">
    <parent link="base_link"/>
    <child link="caster_wheel"/>
    <origin xyz="0.1125 0.0 -0.05" rpy="0 0 0"/>
  </joint>

  <!-- Lidar Joint -->
  <joint name="lidar_joint" type="fixed">
    <parent link="base_link"/>
    <child link="lidar_link"/>
    <origin xyz="0.0 0.0 0.185" rpy="0.0 0.0 0.0"/>
  </joint>

  <!-- Camera Joint -->
  <joint name="camera_joint" type="fixed">
    <parent link="base_link"/>
    <child link="camera_link"/>
    <origin xyz="0.14 0.0 0.13" rpy="0.0 0.0 0.0"/>
  </joint>

  <!-- Camera Optical Joint (rotates frame to ROS camera convention) -->
  <joint name="camera_optical_joint" type="fixed">
    <parent link="camera_link"/>
    <child link="camera_optical_link"/>
    <origin xyz="0 0 0" rpy="-1.5708 0.0 -1.5708"/>
  </joint>

  <!-- Gazebo Plugins -->
  <gazebo>
    <plugin name="differential_drive_controller" filename="libgazebo_ros_diff_drive.so">
      <update_rate>100.0</update_rate>
      <left_joint>left_wheel_joint</left_joint>
      <right_joint>right_wheel_joint</right_joint>
      <wheel_separation>-0.175</wheel_separation>
      <wheel_diameter>0.1</wheel_diameter>
      <max_wheel_torque>20</max_wheel_torque>
      <max_wheel_acceleration>1.0</max_wheel_acceleration>
      <command_topic>cmd_vel</command_topic>
      <odometry_topic>odom</odometry_topic>
      <odometry_frame>odom</odometry_frame>
      <robot_base_frame>base_link</robot_base_frame>
      <publish_odom>true</publish_odom>
      <publish_odom_tf>true</publish_odom_tf>
      <publish_wheel_tf>true</publish_wheel_tf>
    </plugin>
  </gazebo>

  <!-- Base link properties -->
  <gazebo reference="base_link">
    <material>Gazebo/Blue</material>
  </gazebo>

  <!-- Wheel friction -->
  <gazebo reference="left_wheel">
    <material>Gazebo/Black</material>
    <mu1>1.0</mu1>
    <mu2>1.0</mu2>
    <kp>1000000.0</kp>
    <kd>100.0</kd>
  </gazebo>

  <gazebo reference="right_wheel">
    <material>Gazebo/Black</material>
    <mu1>1.0</mu1>
    <mu2>1.0</mu2>
    <kp>1000000.0</kp>
    <kd>100.0</kd>
  </gazebo>

  <!-- Caster wheel properties - low friction for smooth rolling -->
  <gazebo reference="caster_wheel">
    <material>Gazebo/Grey</material>
    <mu1>0.0</mu1>
    <mu2>0.0</mu2>
    <kp>1000000.0</kp>
    <kd>10.0</kd>
  </gazebo>

  <!-- Lidar Plugin -->
  <gazebo reference="lidar_link">
    <sensor type="ray" name="hokuyo">
      <pose>0 0 0 0 0 0</pose>
      <visualize>true</visualize>
      <update_rate>40</update_rate>
      <ray>
        <scan>
          <horizontal>
            <samples>720</samples>
            <resolution>1</resolution>
            <min_angle>-3.14159</min_angle>
            <max_angle>3.14159</max_angle>
          </horizontal>
        </scan>
        <range>
          <min>0.10</min>
          <max>10.0</max>
          <resolution>0.01</resolution>
        </range>
        <noise>
          <type>gaussian</type>
          <mean>0.0</mean>
          <stddev>0.01</stddev>
        </noise>
      </ray>
      <plugin name="gazebo_ros_head_hokuyo_controller" filename="libgazebo_ros_ray_sensor.so">
        <ros>
          <namespace>/</namespace>
          <remapping>~/out:=scan</remapping>
        </ros>
        <output_type>sensor_msgs/LaserScan</output_type>
        <frame_name>lidar_link</frame_name>
      </plugin>
    </sensor>
  </gazebo>

  <!-- RealSense D435 Camera Plugin -->
  <gazebo reference="camera_link">
    <sensor name="camera" type="depth">
      <update_rate>30</update_rate>
      <camera>
        <horizontal_fov>1.51844</horizontal_fov>
        <image>
          <width>640</width>
          <height>480</height>
          <format>R8G8B8</format>
        </image>
        <clip>
          <near>0.1</near>
          <far>10.0</far>
        </clip>
        <noise>
          <type>gaussian</type>
          <mean>0.0</mean>
          <stddev>0.007</stddev>
        </noise>
      </camera>
      <plugin name="camera_controller" filename="libgazebo_ros_camera.so">
        <ros>
          <namespace>/camera</namespace>
          <remapping>image_raw:=color/image_raw</remapping>
          <remapping>depth/image_raw:=depth/image_raw</remapping>
          <remapping>camera_info:=color/camera_info</remapping>
          <remapping>depth/camera_info:=depth/camera_info</remapping>
          <remapping>points:=depth/color/points</remapping>
        </ros>
        <camera_name>camera</camera_name>
        <frame_name>camera_optical_link</frame_name>
        <hack_baseline>0.07</hack_baseline>
        <min_depth>0.1</min_depth>
        <max_depth>10.0</max_depth>
      </plugin>
    </sensor>
  </gazebo>

</robot>